Workbook

Sheet Opt.vs.Act
A1: SOrderNbr | B1: Opt Bund | C1: Actual Bund ? | D1: Bundle Error | E1: Opt_lbs | F1: Actual_lbs ? | G1: lbs Error
A2: {=_xlfn._xlws.SORT(_xlfn.UNIQUE(_xlfn._xlws.FILTER(Optimized_Bundles!B:B, Optimized_Bundles!B:B<>"")))} -> 1000068 | B2: =IFERROR( _xlfn.MAXIFS(Optimized_Bundles!$C:$C, Optimized_Bundles!$B:$B, $A2), "") -> 5 | D2: =B2-C2 -> 5 | E2: 9704 | G2: =E2-F2 -> 9704
A3: 1000085 | B3: =IFERROR( _xlfn.MAXIFS(Optimized_Bundles!$C:$C, Optimized_Bundles!$B:$B, $A3), "") -> 2 | D3: =B3-C3 -> 2 | E3: 3113 | G3: =E3-F3 -> 3113
A4: 1000091 | B4: =IFERROR( _xlfn.MAXIFS(Optimized_Bundles!$C:$C, Optimized_Bundles!$B:$B, $A4), "") -> 1 | D4: =B4-C4 -> 1 | E4: 201 | G4: =E4-F4 -> 201
A5: 1000092 | B5: =IFERROR( _xlfn.MAXIFS(Optimized_Bundles!$C:$C, Optimized_Bundles!$B:$B, $A5), "") -> 1 | D5: =B5-C5 -> 1 | E5: 946 | G5: =E5-F5 -> 946
A6: 1000503 | B6: =IFERROR( _xlfn.MAXIFS(Optimized_Bundles!$C:$C, Optimized_Bundles!$B:$B, $A6), "") -> 1 | D6: =B6-C6 -> 1 | E6: 42 | G6: =E6-F6 -> 42
A7: 1000789 | B7: =IFERROR( _xlfn.MAXIFS(Optimized_Bundles!$C:$C, Optimized_Bundles!$B:$B, $A7), "") -> 0 | D7: =B7-C7 -> 0 | E7: 0 | G7: =E7-F7 -> 0
A8: 1000790 | B8: =IFERROR( _xlfn.MAXIFS(Optimized_Bundles!$C:$C, Optimized_Bundles!$B:$B, $A8), "") -> 0 | D8: =B8-C8 -> 0 | E8: 0 | G8: =E8-F8 -> 0
A9: 1000791 | B9: =IFERROR( _xlfn.MAXIFS(Optimized_Bundles!$C:$C, Optimized_Bundles!$B:$B, $A9), "") -> 0 | D9: =B9-C9 -> 0 | E9: 0 | G9: =E9-F9 -> 0
A10: 1000792 | B10: =IFERROR( _xlfn.MAXIFS(Optimized_Bundles!$C:$C, Optimized_Bundles!$B:$B, $A10), "") -> 0 | D10: =B10-C10 -> 0 | E10: 0 | G10: =E10-F10 -> 0
A11: 1000794 | B11: =IFERROR( _xlfn.MAXIFS(Optimized_Bundles!$C:$C, Optimized_Bundles!$B:$B, $A11), "") -> 0 | D11: =B11-C11 -> 0 | E11: 0 | G11: =E11-F11 -> 0
A12: 1000795 | B12: =IFERROR( _xlfn.MAXIFS(Optimized_Bundles!$C:$C, Optimized_Bundles!$B:$B, $A12), "") -> 0 | D12: =B12-C12 -> 0 | E12: 0 | G12: =E12-F12 -> 0
A13: 1000796 | B13: =IFERROR( _xlfn.MAXIFS(Optimized_Bundles!$C:$C, Optimized_Bundles!$B:$B, $A13), "") -> 0 | D13: =B13-C13 -> 0 | E13: 0 | G13: =E13-F13 -> 0
A14: 1000797 | B14: =IFERROR( _xlfn.MAXIFS(Optimized_Bundles!$C:$C, Optimized_Bundles!$B:$B, $A14), "") -> 1 | D14: =B14-C14 -> 1 | E14: 1019 | G14: =E14-F14 -> 1019
... A118: 1015707 | B118: =IFERROR( _xlfn.MAXIFS(Optimized_Bundles!$C:$C, Optimized_Bundles!$B:$B, $A118), "") -> 2 | D118: =B118-C118 -> 2 | E118: 4189 | G118: =E118-F118 -> 4189
A119: 1015708 | B119: =IFERROR( _xlfn.MAXIFS(Optimized_Bundles!$C:$C, Optimized_Bundles!$B:$B, $A119), "") -> 1 | C119: 1 | D119: =B119-C119 -> 0 | E119: 426 | F119: 343 | G119: =E119-F119 -> 83
A120: 1015709 | B120: =IFERROR( _xlfn.MAXIFS(Optimized_Bundles!$C:$C, Optimized_Bundles!$B:$B, $A120), "") -> 1 | D120: =B120-C120 -> 1 | E120: 165 | G120: =E120-F120 -> 165
A121: 1015710 | B121: =IFERROR( _xlfn.MAXIFS(Optimized_Bundles!$C:$C, Optimized_Bundles!$B:$B, $A121), "") -> 1 | D121: =B121-C121 -> 1 | E121: 44 | G121: =E121-F121 -> 44
A122: 1015713 | B122: =IFERROR( _xlfn.MAXIFS(Optimized_Bundles!$C:$C, Optimized_Bundles!$B:$B, $A122), "") -> 2 | D122: =B122-C122 -> 2 | E122: 103 | G122: =E122-F122 -> 103
A123: 1015714 | B123: =IFERROR( _xlfn.MAXIFS(Optimized_Bundles!$C:$C, Optimized_Bundles!$B:$B, $A123), "") -> 1 | D123: =B123-C123 -> 1 | E123: 136 | G123: =E123-F123 -> 136
A124: 1015716 | B124: =IFERROR( _xlfn.MAXIFS(Optimized_Bundles!$C:$C, Optimized_Bundles!$B:$B, $A124), "") -> 1 | D124: =B124-C124 -> 1 | E124: 346 | G124: =E124-F124 -> 346
A125: 1015718 | B125: =IFERROR( _xlfn.MAXIFS(Optimized_Bundles!$C:$C, Optimized_Bundles!$B:$B, $A125), "") -> 2 | D125: =B125-C125 -> 2 | E125: 2703 | G125: =E125-F125 -> 2703
A126: 1015719 | B126: =IFERROR( _xlfn.MAXIFS(Optimized_Bundles!$C:$C, Optimized_Bundles!$B:$B, $A126), "") -> 1 | D126: =B126-C126 -> 1 | E126: 1438 | G126: =E126-F126 -> 1438
A127: 1015721 | B127: =IFERROR( _xlfn.MAXIFS(Optimized_Bundles!$C:$C, Optimized_Bundles!$B:$B, $A127), "") -> 1 | D127: =B127-C127 -> 1 | E127: 176 | G127: =E127-F127 -> 176
A128: 1015724 | B128: =IFERROR( _xlfn.MAXIFS(Optimized_Bundles!$C:$C, Optimized_Bundles!$B:$B, $A128), "") -> 7 | D128: =B128-C128 -> 7 | E128: 11379 | G128: =E128-F128 -> 11379
A129: 1015731 | B129: =IFERROR( _xlfn.MAXIFS(Optimized_Bundles!$C:$C, Optimized_Bundles!$B:$B, $A129), "") -> 1 | D129: =B129-C129 -> 1 | E129: 85 | G129: =E129-F129 -> 85
A130: 1015732 | B130: =IFERROR( _xlfn.MAXIFS(Optimized_Bundles!$C:$C, Optimized_Bundles!$B:$B, $A130), "") -> 1 | D130: =B130-C130 -> 1 | E130: 80 | G130: =E130-F130 -> 80
A131: 1015733 | B131: =IFERROR( _xlfn.MAXIFS(Optimized_Bundles!$C:$C, Optimized_Bundles!$B:$B, $A131), "") -> 3 | D131: =B131-C131 -> 3 | E131: 5153 | G131: =E131-F131 -> 5153
A132: OrderNbr | B132: =IFERROR( _xlfn.MAXIFS(Optimized_Bundles!$C:$C, Optimized_Bundles!$B:$B, $A132), "") -> 0 | D132: =B132-C132 -> 0 | E132: 0 | G132: =E132-F132 -> 0
B133: =IFERROR( _xlfn.MAXIFS(Optimized_Bundles!$C:$C, Optimized_Bundles!$B:$B, $A133), "") -> 0 | D133: =B133-C133 -> 0 | E133: 0 | G133: =E133-F133 -> 0
B134: =IFERROR( _xlfn.MAXIFS(Optimized_Bundles!$C:$C, Optimized_Bundles!$B:$B, $A134), "") -> 0 | D134: =B134-C134 -> 0 | E134: 0 | G134: =E134-F134 -> 0
B135: =IFERROR( _xlfn.MAXIFS(Optimized_Bundles!$C:$C, Optimized_Bundles!$B:$B, $A135), "") -> 0 | D135: =B135-C135 -> 0 | E135: 0 | G135: =E135-F135 -> 0
B136: =IFERROR( _xlfn.MAXIFS(Optimized_Bundles!$C:$C, Optimized_Bundles!$B:$B, $A136), "") -> 0 | D136: =B136-C136 -> 0 | E136: 0 | G136: =E136-F136 -> 0
B137: =IFERROR( _xlfn.MAXIFS(Optimized_Bundles!$C:$C, Optimized_Bundles!$B:$B, $A137), "") -> 0 | D137: =B137-C137 -> 0 | E137: 0 | G137: =E137-F137 -> 0
B138: =IFERROR( _xlfn.MAXIFS(Optimized_Bundles!$C:$C, Optimized_Bundles!$B:$B, $A138), "") -> 0 | D138: =B138-C138 -> 0 | E138: 0 | G138: =E138-F138 -> 0
B139: =IFERROR( _xlfn.MAXIFS(Optimized_Bundles!$C:$C, Optimized_Bundles!$B:$B, $A139), "") -> 0 | D139: =B139-C139 -> 0 | E139: 0 | G139: =E139-F139 -> 0
B140: =IFERROR( _xlfn.MAXIFS(Optimized_Bundles!$C:$C, Optimized_Bundles!$B:$B, $A140), "") -> 0 | D140: =B140-C140 -> 0 | E140: 0 | G140: =E140-F140 -> 0
B141: =IFERROR( _xlfn.MAXIFS(Optimized_Bundles!$C:$C, Optimized_Bundles!$B:$B, $A141), "") -> 0 | D141: =B141-C141 -> 0 | E141: 0 | G141: =E141-F141 -> 0
B142: =IFERROR( _xlfn.MAXIFS(Optimized_Bundles!$C:$C, Optimized_Bundles!$B:$B, $A142), "") -> 0 | D142: =B142-C142 -> 0 | E142: 0 | G142: =E142-F142 -> 0
B143: =IFERROR( _xlfn.MAXIFS(Optimized_Bundles!$C:$C, Optimized_Bundles!$B:$B, $A143), "") -> 0 | D143: =B143-C143 -> 0 | E143: 0 | G143: =E143-F143 -> 0
...

Sheet Optimized_Bundles
A1: OrderType | B1: OrderNbr | C1: BundleNbr | D1: Bdl_Override | E1: Machine | F1: ReviewedBy | G1: ApprovedBy | H1: InventoryID | I1: Quantity | J1: Pcs/Bundle | K1: TotalPcs | L1: Width_in | M1: Height_in | N1: Length_in | O1: Weight_lbs | P1: UOM | Q1: Description | R1: ShipTo | S1: AddressLine1 | T1: AddressLine2 | U1: City | V1: State | W1: Country | X1: Status | Y1: OrderDate | Z1: ProdReleaseDate | AA1: SchedShipDate | AB1: TargetArrival | AC1: NotBefore | AD1: ShipVia | AE1: LastModifiedOn | AF1: OptimizedOn
A2: SO | B2: 1015317 | C2: ALL | H2: Total_Order | I2: 97 | J2: N/A | K2: 1634 | L2: N/A | M2: N/A | N2: N/A | O2: 473 | Q2: Total Order Summary | R2: CRI Tech Corp-Shop | S2: 5340 W Robindale Road | U2: Las Vegas | V2: NV | W2: US | X2: Shipping | Y2: 2025-11-11 | Z2: 2025-11-11 | AA2: 2025-11-11 | AD2: COMMONCARRIER | AE2: 2025-11-18 | AF2: 2025-12-15
A3: SO | B3: 1015317 | C3: 1_ALL | E3: MIXED | H3: Total_Bundle_1 | I3: 42 | J3: N/A | K3: 696 | L3: 21 | M3: 8 | N3: 145 | O3: 205 | Q3: Bundle 1 Summary | R3: CRI Tech Corp-Shop | S3: 5340 W Robindale Road | U3: Las Vegas | V3: NV | W3: US | X3: Shipping | Y3: 2025-11-11 | Z3: 2025-11-11 | AA3: 2025-11-11 | AD3: COMMONCARRIER | AE3: 2025-11-18 | AF3: 2025-12-15
A4: SO | B4: 1015317 | C4: 1 | E4: MIXED | H4: 2LLEM.4.15OBL | I4: 34 | J4: 20 | K4: 680 | L4: 10 | M4: 4 | N4: 8 | O4: 5 | P4: BOX20 | Q4: 1-5/8" End Mount 4 inches (Premium Onyx Black) Box of 20 | R4: CRI Tech Corp-Shop | S4: 5340 W Robindale Road | U4: Las Vegas | V4: NV | W4: US | X4: Shipping | Y4: 2025-11-11 | Z4: 2025-11-11 | AA4: 2025-11-11 | AD4: COMMONCARRIER | AE4: 2025-11-18 | AF4: 2025-12-15
A5: SO | B5: 1015317 | C5: 1 | E5: MIXED | H5: Pack_Angle_3680 | I5: 1 | J5: 4 | K5: 4 | L5: 3 | M5: 0 | N5: 144 | O5: 12 | Q5: PRINTED ANGLEBOARD | R5: CRI Tech Corp-Shop | S5: 5340 W Robindale Road | U5: Las Vegas | V5: NV | W5: US | X5: Shipping | Y5: 2025-11-11 | Z5: 2025-11-11 | AA5: 2025-11-11 | AD5: COMMONCARRIER | AE5: 2025-11-18 | AF5: 2025-12-15
A6: SO | B6: 1015317 | C6: 1 | E6: MIXED | H6: Pack_1x4x19_Dun_3680 | I6: 1 | J6: 2 | K6: 2 | L6: 4 | M6: 1 | N6: 19 | O6: 2 | Q6: 1" X 4" X 19" DUNNAGE | R6: CRI Tech Corp-Shop | S6: 5340 W Robindale Road | U6: Las Vegas | V6: NV | W6: US | X6: Shipping | Y6: 2025-11-11 | Z6: 2025-11-11 | AA6: 2025-11-11 | AD6: COMMONCARRIER | AE6: 2025-11-18 | AF6: 2025-12-15
A7: SO | B7: 1015317 | C7: 1 | E7: MIXED | H7: Pack_2x3x19_Dun_3680 | I7: 1 | J7: 2 | K7: 2 | L7: 3 | M7: 1 | N7: 19 | O7: 4 | Q7: 2" X 3" X 19" DUNNAGE | R7: CRI Tech Corp-Shop | S7: 5340 W Robindale Road | U7: Las Vegas | V7: NV | W7: US | X7: Shipping | Y7: 2025-11-11 | Z7: 2025-11-11 | AA7: 2025-11-11 | AD7: COMMONCARRIER | AE7: 2025-11-18 | AF7: 2025-12-15
A8: SO | B8: 1015317 | C8: 1 | E8: MIXED | H8: Pack_Sub_Bndl_Wrp_3680 | I8: 1 | J8: 2 | K8: 2 | L8: 19 | M8: 0 | N8: 144 | O8: 5 | Q8: Sub-Bundle Wrap - Crepe Paper/Stretch Film | R8: CRI Tech Corp-Shop | S8: 5340 W Robindale Road | U8: Las Vegas | V8: NV | W8: US | X8: Shipping | Y8: 2025-11-11 | Z8: 2025-11-11 | AA8: 2025-11-11 | AD8: COMMONCARRIER | AE8: 2025-11-18 | AF8: 2025-12-15
A9: SO | B9: 1015317 | C9: 1 | E9: MIXED | H9: Pack_Mst_Bndl_Wrp_3680 | I9: 1 | J9: 2 | K9: 2 | L9: 19 | M9: 0 | N9: 144 | O9: 1 | Q9: Master Bundle - Stretch Wrap | R9: CRI Tech Corp-Shop | S9: 5340 W Robindale Road | U9: Las Vegas | V9: NV | W9: US | X9: Shipping | Y9: 2025-11-11 | Z9: 2025-11-11 | AA9: 2025-11-11 | AD9: COMMONCARRIER | AE9: 2025-11-18 | AF9: 2025-12-15
A10: SO | B10: 1015317 | C10: 1 | E10: MIXED | H10: Pack_Pad_19_3680 | I10: 1 | J10: 2 | K10: 2 | L10: 19 | M10: 0 | N10: 144 | O10: 6 | Q10: PAD - 19" X 144" DW ECT #3 WHITE | R10: CRI Tech Corp-Shop | S10: 5340 W Robindale Road | U10: Las Vegas | V10: NV | W10: US | X10: Shipping | Y10: 2025-11-11 | Z10: 2025-11-11 | AA10: 2025-11-11 | AD10: COMMONCARRIER | AE10: 2025-11-18 | AF10: 2025-12-15
A11: SO | B11: 1015317 | C11: 1 | E11: MIXED | H11: Pack_Lumber_3680 | I11: 2 | J11: 1 | K11: 2 | L11: 4 | M11: 1 | N11: 144 | O11: 6 | Q11: COMMON LUMBER - 1" X 4" X 12' | R11: CRI Tech Corp-Shop | S11: 5340 W Robindale Road | U11: Las Vegas | V11: NV | W11: US | X11: Shipping | Y11: 2025-11-11 | Z11: 2025-11-11 | AA11: 2025-11-11 | AD11: COMMONCARRIER | AE11: 2025-11-18 | AF11: 2025-12-15
A12: SO | B12: 1015317 | C12: 2_ALL | E12: MACH5 | H12: Total_Bundle_2 | I12: 55 | J12: N/A | K12: 938 | L12: 14 | M12: 14 | N12: 145 | O12: 267 | Q12: Bundle 2 Summary | R12: CRI Tech Corp-Shop | S12: 5340 W Robindale Road | U12: Las Vegas | V12: NV | W12: US | X12: Shipping | Y12: 2025-11-11 | Z12: 2025-11-11 | AA12: 2025-11-11 | AD12: COMMONCARRIER | AE12: 2025-11-18 | AF12: 2025-12-15
A13: SO | B13: 1015317 | C13: 2 | E13: MACH5 | H13: 2LLEM.4.15OBL | I13: 46 | J13: 20 | K13: 920 | L13: 4 | M13: 10 | N13: 8 | O13: 5 | P13: BOX20 | Q13: 1-5/8" End Mount 4 inches (Premium Onyx Black) Box of 20 | R13: CRI Tech Corp-Shop | S13: 5340 W Robindale Road | U13: Las Vegas | V13: NV | W13: US | X13: Shipping | Y13: 2025-11-11 | Z13: 2025-11-11 | AA13: 2025-11-11 | AD13: COMMONCARRIER | AE13: 2025-11-18 | AF13: 2025-12-15
A14: SO | B14: 1015317 | C14: 2 | E14: MACH5 | H14: Pack_Angle_3680 | I14: 1 | J14: 4 | K14: 4 | L14: 3 | M14: 0 | N14: 144 | O14: 12 | Q14: PRINTED ANGLEBOARD | R14: CRI Tech Corp-Shop | S14: 5340 W Robindale Road | U14: Las Vegas | V14: NV | W14: US | X14: Shipping | Y14: 2025-11-11 | Z14: 2025-11-11 | AA14: 2025-11-11 | AD14: COMMONCARRIER | AE14: 2025-11-18 | AF14: 2025-12-15
A15: SO | B15: 1015317 | C15: 2 | E15: MACH5 | H15: Pack_1x4x19_Dun_3680 | I15: 1 | J15: 2 | K15: 2 | L15: 4 | M15: 1 | N15: 19 | O15: 2 | Q15: 1" X 4" X 19" DUNNAGE | R15: CRI Tech Corp-Shop | S15: 5340 W Robindale Road | U15: Las Vegas | V15: NV | W15: US | X15: Shipping | Y15: 2025-11-11 | Z15: 2025-11-11 | AA15: 2025-11-11 | AD15: COMMONCARRIER | AE15: 2025-11-18 | AF15: 2025-12-15
A16: SO | B16: 1015317 | C16: 2 | E16: MACH5 | H16: Pack_2x3x19_Dun_3680 | I16: 1 | J16: 2 | K16: 2 | L16: 3 | M16: 1 | N16: 19 | O16: 4 | Q16: 2" X 3" X 19" DUNNAGE | R16: CRI Tech Corp-Shop | S16: 5340 W Robindale Road | U16: Las Vegas | V16: NV | W16: US | X16: Shipping | Y16: 2025-11-11 | Z16: 2025-11-11 | AA16: 2025-11-11 | AD16: COMMONCARRIER | AE16: 2025-11-18 | AF16: 2025-12-15
A17: SO | B17: 1015317 | C17: 2 | E17: MACH5 | H17: Pack_Sub_Bndl_Wrp_3680 | I17: 1 | J17: 2 | K17: 2 | L17: 19 | M17: 0 | N17: 144 | O17: 5 | Q17: Sub-Bundle Wrap - Crepe Paper/Stretch Film | R17: CRI Tech Corp-Shop | S17: 5340 W Robindale Road | U17: Las Vegas | V17: NV | W17: US | X17: Shipping | Y17: 2025-11-11 | Z17: 2025-11-11 | AA17: 2025-11-11 | AD17: COMMONCARRIER | AE17: 2025-11-18 | AF17: 2025-12-15
A18: SO | B18: 1015317 | C18: 2 | E18: MACH5 | H18: Pack_Mst_Bndl_Wrp_3680 | I18: 1 | J18: 2 | K18: 2 | L18: 19 | M18: 0 | N18: 144 | O18: 1 | Q18: Master Bundle - Stretch Wrap | R18: CRI Tech Corp-Shop | S18: 5340 W Robindale Road | U18: Las Vegas | V18: NV | W18: US | X18: Shipping | Y18: 2025-11-11 | Z18: 2025-11-11 | AA18: 2025-11-11 | AD18: COMMONCARRIER | AE18: 2025-11-18 | AF18: 2025-12-15
A19: SO | B19: 1015317 | C19: 2 | E19: MACH5 | H19: Pack_Pad_19_3680 | I19: 1 | J19: 2 | K19: 2 | L19: 19 | M19: 0 | N19: 144 | O19: 6 | Q19: PAD - 19" X 144" DW ECT #3 WHITE | R19: CRI Tech Corp-Shop | S19: 5340 W Robindale Road | U19: Las Vegas | V19: NV | W19: US | X19: Shipping | Y19: 2025-11-11 | Z19: 2025-11-11 | AA19: 2025-11-11 | AD19: COMMONCARRIER | AE19: 2025-11-18 | AF19: 2025-12-15
A20: SO | B20: 1015317 | C20: 2 | E20: MACH5 | H20: Pack_Pad_10_3680 | I20: 1 | J20: 2 | K20: 2 | L20: 10 | M20: 0 | N20: 144 | O20: 4 | Q20: PAD - 10" X 144" DW ECT #3 WHITE | R20: CRI Tech Corp-Shop | S20: 5340 W Robindale Road | U20: Las Vegas | V20: NV | W20: US | X20: Shipping | Y20: 2025-11-11 | Z20: 2025-11-11 | AA20: 2025-11-11 | AD20: COMMONCARRIER | AE20: 2025-11-18 | AF20: 2025-12-15
A21: SO | B21: 1015317 | C21: 2 | E21: MACH5 | H21: Pack_Lumber_3680 | I21: 2 | J21: 1 | K21: 2 | L21: 4 | M21: 1 | N21: 144 | O21: 6 | Q21: COMMON LUMBER - 1" X 4" X 12' | R21: CRI Tech Corp-Shop | S21: 5340 W Robindale Road | U21: Las Vegas | V21: NV | W21: US | X21: Shipping | Y21: 2025-11-11 | Z21: 2025-11-11 | AA21: 2025-11-11 | AD21: COMMONCARRIER | AE21: 2025-11-18 | AF21: 2025-12-15
A23: SO | B23: 1015716 | C23: ALL | H23: Total_Order | I23: 22 | J23: N/A | K23: 99 | L23: N/A | M23: N/A | N23: N/A | O23: 346 | Q23: Total Order Summary | R23: Westrend Exteriors Inc. | S23: Customer Pickup | W23: CA | X23: Open | Y23: 2025-12-12 | Z23: 2025-12-12 | AA23: 2025-12-12 | AD23: COMMONCARRIER | AE23: 2025-12-15 | AF23: 2025-12-15
A24: SO | B24: 1015716 | C24: 1_ALL | E24: MIXED | H24: Total_Bundle_1 | I24: 22 | J24: N/A | K24: 99 | L24: 21 | M24: 15 | N24: 145 | O24: 346 | Q24: Bundle 1 Summary | R24: Westrend Exteriors Inc. | S24: Customer Pickup | W24: CA | X24: Open | Y24: 2025-12-12 | Z24: 2025-12-12 | AA24: 2025-12-12 | AD24: COMMONCARRIER | AE24: 2025-12-15 | AF24: 2025-12-15
A25: SO | B25: 1015716 | C25: 1 | E25: MIXED | H25: 2X4LL.145.15BEE | I25: 10 | J25: 4 | K25: 40 | L25: 4 | M25: 4 | N25: 145 | O25: 29 | P25: BOX2 | Q25: 1-5/8" x 4" Link & Lock 12 feet (Premium Beechwood) Box of 2 | R25: Westrend Exteriors Inc. | S25: Customer Pickup | W25: CA | X25: Open | Y25: 2025-12-12 | Z25: 2025-12-12 | AA25: 2025-12-12 | AD25: COMMONCARRIER | AE25: 2025-12-15 | AF25: 2025-12-15
A26: SO | B26: 1015716 | C26: 1 | E26: MIXED | H26: 2LLEM.4.15OBL | I26: 2 | J26: 20 | K26: 40 | L26: 10 | M26: 4 | N26: 8 | O26: 5 | P26: BOX20 | Q26: 1-5/8" End Mount 4 inches (Premium Onyx Black) Box of 20 | R26: Westrend Exteriors Inc. | S26: Customer Pickup | W26: CA | X26: Open | Y26: 2025-12-12 | Z26: 2025-12-12 | AA26: 2025-12-12 | AD26: COMMONCARRIER | AE26: 2025-12-15 | AF26: 2025-12-15
A27: SO | B27: 1015716 | C27: 1 | E27: MIXED | H27: Pack_62Filler | I27: 2 | J27: 1 | K27: 2 | L27: 6 | M27: 2 | N27: 144 | O27: 5 | Q27: 6"x2" FILLER BOX | R27: Westrend Exteriors Inc. | S27: Customer Pickup | W27: CA | X27: Open | Y27: 2025-12-12 | Z27: 2025-12-12 | AA27: 2025-12-12 | AD27: COMMONCARRIER | AE27: 2025-12-15 | AF27: 2025-12-15
A28: SO | B28: 1015716 | C28: 1 | E28: MIXED | H28: Pack_44Filler | I28: 1 | J28: 1 | K28: 1 | L28: 4 | M28: 4 | N28: 144 | O28: 4 | Q28: 4"x4" FILLER BOX | R28: Westrend Exteriors Inc. | S28: Customer Pickup | W28: CA | X28: Open | Y28: 2025-12-12 | Z28: 2025-12-12 | AA28: 2025-12-12 | AD28: COMMONCARRIER | AE28: 2025-12-15 | AF28: 2025-12-15
A29: SO | B29: 1015716 | C29: 1 | E29: MIXED | H29: Pack_Angle_3680 | I29: 1 | J29: 4 | K29: 4 | L29: 3 | M29: 0 | N29: 144 | O29: 12 | Q29: PRINTED ANGLEBOARD | R29: Westrend Exteriors Inc. | S29: Customer Pickup | W29: CA | X29: Open | Y29: 2025-12-12 | Z29: 2025-12-12 | AA29: 2025-12-12 | AD29: COMMONCARRIER | AE29: 2025-12-15 | AF29: 2025-12-15
A30: SO | B30: 1015716 | C30: 1 | E30: MIXED | H30: Pack_1x4x19_Dun_3680 | I30: 1 | J30: 2 | K30: 2 | L30: 4 | M30: 1 | N30: 19 | O30: 2 | Q30: 1" X 4" X 19" DUNNAGE | R30: Westrend Exteriors Inc. | S30: Customer Pickup | W30: CA | X30: Open | Y30: 2025-12-12 | Z30: 2025-12-12 | AA30: 2025-12-12 | AD30: COMMONCARRIER | AE30: 2025-12-15 | AF30: 2025-12-15
A31: SO | B31: 1015716 | C31: 1 | E31: MIXED | H31: Pack_2x3x19_Dun_3680 | I31: 1 | J31: 2 | K31: 2 | L31: 3 | M31: 1 | N31: 19 | O31: 4 | Q31: 2" X 3" X 19" DUNNAGE | R31: Westrend Exteriors Inc. | S31: Customer Pickup | W31: CA | X31: Open | Y31: 2025-12-12 | Z31: 2025-12-12 | AA31: 2025-12-12 | AD31: COMMONCARRIER | AE31: 2025-12-15 | AF31: 2025-12-15
A32: SO | B32: 1015716 | C32: 1 | E32: MIXED | H32: Pack_Sub_Bndl_Wrp_3680 | I32: 1 | J32: 2 | K32: 2 | L32: 19 | M32: 0 | N32: 144 | O32: 5 | Q32: Sub-Bundle Wrap - Crepe Paper/Stretch Film | R32: Westrend Exteriors Inc. | S32: Customer Pickup | W32: CA | X32: Open | Y32: 2025-12-12 | Z32: 2025-12-12 | AA32: 2025-12-12 | AD32: COMMONCARRIER | AE32: 2025-12-15 | AF32: 2025-12-15
A33: SO | B33: 1015716 | C33: 1 | E33: MIXED | H33: Pack_Mst_Bndl_Wrp_3680 | I33: 1 | J33: 2 | K33: 2 | L33: 19 | M33: 0 | N33: 144 | O33: 1 | Q33: Master Bundle - Stretch Wrap | R33: Westrend Exteriors Inc. | S33: Customer Pickup | W33: CA | X33: Open | Y33: 2025-12-12 | Z33: 2025-12-12 | AA33: 2025-12-12 | AD33: COMMONCARRIER | AE33: 2025-12-15 | AF33: 2025-12-15
A34: SO | B34: 1015716 | C34: 1 | E34: MIXED | H34: Pack_Pad_19_3680 | I34: 1 | J34: 2 | K34: 2 | L34: 19 | M34: 0 | N34: 144 | O34: 6 | Q34: PAD - 19" X 144" DW ECT #3 WHITE | R34: Westrend Exteriors Inc. | S34: Customer Pickup | W34: CA | X34: Open | Y34: 2025-12-12 | Z34: 2025-12-12 | AA34: 2025-12-12 | AD34: COMMONCARRIER | AE34: 2025-12-15 | AF34: 2025-12-15
A35: SO | B35: 1015716 | C35: 1 | E35: MIXED | H35: Pack_Pad_13_3680 | I35: 1 | J35: 2 | K35: 2 | L35: 13 | M35: 0 | N35: 144 | O35: 4 | Q35: PAD - 13" X 144" DW ECT #3 WHITE | R35: Westrend Exteriors Inc. | S35: Customer Pickup | W35: CA | X35: Open | Y35: 2025-12-12 | Z35: 2025-12-12 | AA35: 2025-12-12 | AD35: COMMONCARRIER | AE35: 2025-12-15 | AF35: 2025-12-15
A37: MC | B37: 1000791 | C37: 0_ALL | H37: Missing_SKUs | I37: 6 | J37: N/A | K37: N/A | L37: N/A | M37: N/A | N37: N/A | O37: N/A | Q37: Missing SKUs Summary | R37: Phantom Mfg. (INT'L) Ltd . | S37: P.O. Box 2310 | U37: Abbotsford | V37: BC | W37: CA | X37: Open | Y37: 2025-11-20 | Z37: 2025-11-27 | AA37: 2025-11-27 | AD37: COMMONCARRIER | AE37: 2025-12-12 | AF37: 2025-12-15
A38: MC | B38: 1000791 | C38: 0 | H38: MC.PHA102328.15DCR | I38: 3 | J38: N/A | K38: N/A | L38: N/A | M38: N/A | N38: N/A | O38: N/A | P38: EA | Q38: PHA - Side Track Cover - Executive - Dark Cedar - Finished Good | R38: Phantom Mfg. (INT'L) Ltd . | S38: P.O. Box 2310 | U38: Abbotsford | V38: BC | W38: CA | X38: Open | Y38: 2025-11-20 | Z38: 2025-11-27 | AA38: 2025-11-27 | AD38: COMMONCARRIER | AE38: 2025-12-12 | AF38: 2025-12-15
A39: MC | B39: 1000791 | C39: 0 | H39: MC.PHA102329.15DCR | I39: 3 | J39: N/A | K39: N/A | L39: N/A | M39: N/A | N39: N/A | O39: N/A | P39: EA | Q39: PHA - Side Track Standard - Executive - Dark Cedar - Finished Good | R39: Phantom Mfg. (INT'L) Ltd . | S39: P.O. Box 2310 | U39: Abbotsford | V39: BC | W39: CA | X39: Open | Y39: 2025-11-20 | Z39: 2025-11-27 | AA39: 2025-11-27 | AD39: COMMONCARRIER | AE39: 2025-12-12 | AF39: 2025-12-15
A41: SO | B41: 1015677 | C41: ALL | H41: Total_Order | I41: 10 | J41: N/A | K41: 48 | L41: N/A | M41: N/A | N41: N/A | O41: 300 | Q41: Total Order Summary | R41: Nulook Exteriors-Shop | S41: 14331 Ewing Ave S | U41: Burnsville | V41: MN | W41: US | X41: Shipping | Y41: 2025-12-10 | Z41: 2025-12-10 | AA41: 2025-12-10 | AD41: COMMONCARRIER | AE41: 2025-12-12 | AF41: 2025-12-15
A42: SO | B42: 1015677 | C42: 1_ALL | E42: MACH5 | H42: Total_Bundle_1 | I42: 10 | J42: N/A | K42: 48 | L42: 8 | M42: 8 | N42: 289 | O42: 300 | Q42: Bundle 1 Summary | R42: Nulook Exteriors-Shop | S42: 14331 Ewing Ave S | U42: Burnsville | V42: MN | W42: US | X42: Shipping | Y42: 2025-12-10 | Z42: 2025-12-10 | AA42: 2025-12-10 | AD42: COMMONCARRIER | AE42: 2025-12-12 | AF42: 2025-12-15
A43: SO | B43: 1015677 | C43: 1 | E43: MACH5 | H43: 6VR.289.15BEE | I43: 2 | J43: 8 | K43: 16 | L43: 7 | M43: 2 | N43: 289 | O43: 112 | P43: BOX8 | Q43: 6" V-Groove - Rib 24 feet (Premium Beechwood) Box of 8 | R43: Nulook Exteriors-Shop | S43: 14331 Ewing Ave S | U43: Burnsville | V43: MN | W43: US | X43: Shipping | Y43: 2025-12-10 | Z43: 2025-12-10 | AA43: 2025-12-10 | AD43: COMMONCARRIER | AE43: 2025-12-12 | AF43: 2025-12-15
...
