Workbook

Sheet Error+2bdl
A1: Details for Count of Act Bund - Bundle Error: 2
A3: SOrderNbr | B3: Opt Bund | C3: Act Bund | D3: Bundle Error | E3: Opt_lbs | F3: Act_lbs | G3: Comment - missing data | H3: Comment on packing image | I3: Column1
A4: 1014541 | B4: 3 | C4: 1 | D4: 2 | E4: 816 | F4: 717 | G4: no missing data | H4: That should have been doen in 1 bundle, or atleast two bundles. Review | I4: #VALUE!
A5: 1014505 | B5: 3 | C5: 1 | D5: 2 | E5: 2000 | F5: 2006 | G5: no missing data | H5: This could have been completed in 1 bundle, with components on top or nestled into bundle 1. All 145 length are noted as components in file | I5: #VALUE!
A6: 1014450 | B6: 3 | C6: 1 | D6: 2 | E6: 1264 | F6: 1161 | G6: no missing data | H6: This could have been completed in 1 bundle, with components on top or nestled into bundle 1. All 145 length are noted as components in file | I6: #VALUE!
A7: 1014339 | B7: 3 | C7: 1 | D7: 2 | E7: 1189 | F7: 1140 | G7: no missing data | H7: This could have been completed in 1 bundle, with components on top or nestled into bundle 1. All 145 length are noted as components in file | I7: #VALUE!
A8: 1014495 | B8: 4 | C8: 2 | D8: 2 | E8: 2365 | F8: 2255 | G8: no missing data | H8: Bundle 2 and 3 should have been combined with bundle 2….. | I8: #VALUE!
A9: 1014380 | B9: 4 | C9: 2 | D9: 2 | E9: 1695 | F9: 1583 | G9: no missing data | H9: Link-n-locks in bundle 4 could have been combined-added to bundle 1. Bundle 2&3 could have been combined | I9: #VALUE!
A10: 1013988 | B10: 4 | C10: 2 | D10: 2 | E10: 3172 | F10: 3036 | G10: 2ESLV.2.15BEE missing | H10: Bundle 1 and 2 combine, bundle 3 and 4 combine. Bundle 4 all components, could have gone on bundle 3. laying bundle 2 comonets on side 3 high, 3 wide would have been good and the remaining components could have been compined on bundle 3 | I10: #VALUE!
A11: 1014504 | B11: 5 | C11: 3 | D11: 2 | E11: 3054 | F11: 2976 | G11: no missing data | H11: Bundles 1 and 4 have 12 and 14 sub-bundles of 2x6LL. Not sure why it wouldn’t bundle 11 by combining bundles 2, 3 and 5. | I11: #VALUE!
A12: 1014439 | B12: 5 | C12: 3 | D12: 2 | E12: 3142 | F12: 3012 | G12: no missing data | H12: Should be able to add bundle 2 remaining LLSTIFF.289 to tbundle 1 on the flat and then add the remaining single peice of 2x6LLL.289 from bundle 5 to bundel 1on the flat. | I12: #VALUE!
A13: 1014455 | B13: 5 | C13: 3 | D13: 2 | E13: 2951 | F13: 3053 | G13: no missing data | H13: Not sure how to reduce by 2 bundles, but should be able to place bundle 5 on bundle 4. | I13: #VALUE!

Sheet Error-9bdl
A1: Details for Count of Act Bund - Bundle Error: -9
A3: SOrderNbr | B3: Opt Bund | C3: Act Bund | D3: Bundle Error | E3: Opt_lbs | F3: Act_lbs | G3: Comment - missing data | H3: Comment on packing image | I3: Column1
A4: 1014442 | B4: 24 | C4: 33 | D4: -9 | E4: 41911 | F4: 43451 | G4: No missing dat or bundle "0" | H4: Tightly Packaged, 7-8 skus had 8" and 6" LL mixed for a compact order….keeping them separate in this cas, would have added bundles to the optimized solution. Probably makes sense to only mix large number of SKU's on last bundle so that thedeliverey of SKU's is simpler. | I4: #VALUE!

Sheet Error+5bdl
A1: Details for Count of Act Bund - Bundle Error: 5
A3: SOrderNbr | B3: Opt Bund | C3: Act Bund | D3: Bundle Error | E3: Opt_lbs | F3: Act_lbs | G3: Comment - missing data | H3: Comment on packing image | I3: Column1
A4: 1014409 | B4: 14 | C4: 9 | D4: 5 | E4: 11949 | F4: 11621 | G4: No missing dat or bundle "0" | H4: Could have gone one more row wider to reduce qty's possibly. This would have generated 4 more pices per bundle. That would have reduced bundles by 3…..plus the last 3 budles could have been combined into one, so it would have been close. | I4: #VALUE!

Sheet Error-2bdl
A1: Details for Count of Act Bund - Bundle Error: -2
A3: Error- | B3: Opt Bund | C3: Act Bund | D3: Bundle Error | E3: Opt_lbs | F3: Act_lbs | G3: Comment - missing data | H3: Comment on packing image | I3: Column1
A4: 1014561 | B4: 5 | C4: 7 | D4: -2 | E4: 10150 | F4: 10558 | G4: no missing SKUs | H4: 6VR is packages 10 on edge wide, LB ussualy only package 9 wide, even thogu they go 3 length wise which is wider than the 10 width wise. I think they may only go 2high on the lengthwise stack, while the program did 3…....weight is just under 1000kgs which larger bundles. That wold be the difference of 2 bundles less with SW | I4: #VALUE!
A5: 1014488 | B5: 6 | C5: 8 | D5: -2 | E5: 12093 | F5: 12454 | G5: no missing SKUs | H5: 6VR is packages 10 on edge wide, LB ussualy only package 9 wide, even thogu they go 3 length wise which is wider than the 10 width wise. I think they may only go 2high on the lengthwise stack, while the program did 3…....weight is just under 1000kgs which larger bundles. That wold be the difference of 2 bundles less with SW | I5: #VALUE!
A6: 1014381 | B6: 9 | C6: 11 | D6: -2 | E6: 5854 | F6: 6067 | G6: no missing SKUs | H6: each bundle had 12 LL sub-bundles….packaged two different ways which optimized the total number of bundles to 9 instead of 11 which was a savigs of 2 bundles | I6: #VALUE!
A7: 1011679 | B7: 13 | C7: 15 | D7: -2 | E7: 20046 | F7: 20626 | G7: no missing SKUs | H7: Very large order, which was packaged very tightly and quite posssible to package with 2 more bundles due to the complexity and the number of different SKU's. | I7: #VALUE!

Sheet Error-1bdl
A1: Details for Count of Act Bund - Bundle Error: -1
A3: SOrderNbr | B3: Opt Bund | C3: Act Bund | D3: Bundle Error | E3: Opt_lbs | F3: Act_lbs
A4: 1014550 | B4: 1 | C4: 2 | D4: -1 | E4: 72 | F4: 82
A5: 1014546 | B5: 1 | C5: 2 | D5: -1 | E5: 82 | F5: 79
A6: 1014524 | B6: 1 | C6: 2 | D6: -1 | E6: 104 | F6: 101
A7: 1014507 | B7: 1 | C7: 2 | D7: -1 | E7: 93 | F7: 95
A8: 1014468 | B8: 1 | C8: 2 | D8: -1 | E8: 951 | F8: 1008
A9: 1014240 | B9: 1 | C9: 2 | D9: -1 | E9: 1134 | F9: 528
A10: 1014379 | B10: 1 | C10: 2 | D10: -1 | E10: 737 | F10: 763
A11: 1014548 | B11: 2 | C11: 3 | D11: -1 | E11: 2692 | F11: 2833
A12: 1014431 | B12: 4 | C12: 5 | D12: -1 | E12: 4186 | F12: 4081
A13: 1014335 | B13: 4 | C13: 5 | D13: -1 | E13: 6788 | F13: 6964
A14: 1014523 | B14: 5 | C14: 6 | D14: -1 | E14: 6200 | F14: 6146
A15: 1014039 | B15: 6 | C15: 7 | D15: -1 | E15: 11412 | F15: 11616
... A17: 1014319 | B17: 8 | C17: 9 | D17: -1 | E17: 11601 | F17: 11482

Sheet Error+1bdl
A1: Details for Count of Act Bund - Bundle Error: 1
A3: SOrderNbr | B3: Opt Bund | C3: Act Bund | D3: Bundle Error | E3: Opt_lbs | F3: Act_lbs
A4: 1014558 | B4: 2 | C4: 1 | D4: 1 | E4: 561 | F4: 487
A5: 1014549 | B5: 2 | C5: 1 | D5: 1 | E5: 1319 | F5: 1321
A6: 1014534 | B6: 2 | C6: 1 | D6: 1 | E6: 1059 | F6: 1049
A7: 1014525 | B7: 2 | C7: 1 | D7: 1 | E7: 290 | F7: 269
A8: 1014520 | B8: 2 | C8: 1 | D8: 1 | E8: 1264 | F8: 1261
A9: 1014518 | B9: 2 | C9: 1 | D9: 1 | E9: 683 | F9: 615
A10: 1014509 | B10: 2 | C10: 1 | D10: 1 | E10: 1808 | F10: 1755
A11: 1014487 | B11: 2 | C11: 1 | D11: 1 | E11: 1925 | F11: 1956
A12: 1014121 | B12: 2 | C12: 1 | D12: 1 | E12: 683 | F12: 602
A13: 1014332 | B13: 2 | C13: 1 | D13: 1 | E13: 640 | F13: 608
A14: 1014484 | B14: 2 | C14: 1 | D14: 1 | E14: 406 | F14: 353
A15: 1014480 | B15: 2 | C15: 1 | D15: 1 | E15: 1306 | F15: 1299
... A33: 1014369 | B33: 8 | C33: 7 | D33: 1 | E33: 12154 | F33: 11539

Sheet Pivot-Analysis
AL2: R2DA | AR2: Current file | AS2: R2DA1 | AT2: R2DA | AU2: R2D
B3: Count of Act Bund | C3: Column Labels | AL3: Row Label (Error: OPT - ACTUAL) | AM3: Count | AN3: Abs Dev | AO3: Sq Dev | AQ3: Metric | AR3: Result (live) | AS3: Result (live) | AT3: Result (live) | AU3: Result (live)
B4: Row Labels | C4: 1 | D4: 2 | E4: 3 | F4: 4 | G4: 5 | H4: 6 | I4: 7 | J4: 8 | K4: 9 | L4: 11 | M4: 15 | N4: 33 | O4: Grand Total | AL4: -9 | AM4: 1 | AN4: =ABS(AL4) -> 9 | AO4: =AL4^2 -> 81 | AQ4: Total Count | AR4: =SUM(AM4:AM103) -> 126 | AS4: 126 | AT4: 126 | AU4: 126
B5: -9 | N5: 1 | O5: 1 | P5: =GETPIVOTDATA("Act Bund",$B$3,"Bundle Error",-9)/GETPIVOTDATA("Act Bund",$B$3) -> 0.0079365079 | Q5: =P7+P8+P9+P6+P10+P5+P11 -> 1 | AL5: -2 | AM5: 4 | AN5: =ABS(AL5) -> 2 | AO5: =AL5^2 -> 4 | AQ5: Mean Absolute Deviation (MAD) | AR5: =IF(SUM(AM4:AM103)=0,NA(),SUMPRODUCT(AM4:AM103,AN4:AN103)/SUM(AM4:AM103)) -> 0.68253968 | AS5: 0.66666667 | AT5: 0.66666667 | AU5: 0.6984127
B6: -2 | I6: 1 | J6: 1 | L6: 1 | M6: 1 | O6: 4 | P6: =GETPIVOTDATA("Act Bund",$B$3,"Bundle Error",-2)/GETPIVOTDATA("Act Bund",$B$3) -> 0.031746032 | AL6: -1 | AM6: 14 | AN6: =ABS(AL6) -> 1 | AO6: =AL6^2 -> 1 | AQ6: Root Mean Square Deviation (RMSD) | AR6: =IF(SUM(AM4:AM103)=0,NA(),SQRT(SUMPRODUCT(AM4:AM103,AO4:AO103)/SUM(AM4:AM103))) -> 1.2786402 | AS6: 1.272418 | AT6: 1.272418 | AU6: 1.2909944
B7: -1 | D7: 7 | E7: 1 | G7: 2 | H7: 1 | I7: 1 | K7: 2 | O7: 14 | P7: =GETPIVOTDATA("Act Bund",$B$3,"Bundle Error",-1)/GETPIVOTDATA("Act Bund",$B$3) -> 0.11111111 | AL7: 0 | AM7: 66 | AN7: =ABS(AL7) -> 0 | AO7: =AL7^2 -> 0 | AQ7: % within ±1 | AR7: =IF(SUM(AM4:AM103)=0,NA(),SUMIFS(AM4:AM103,AL4:AL103,">=-1",AL4:AL103,"<=1")/SUM(AM4:AM103)) -> 0.87301587 | AS7: 0.87301587 | AT7: 0.87301587 | AU7: 0.88095238
B8: 0 | C8: 49 | D8: 6 | E8: 5 | F8: 3 | G8: 2 | I8: 1 | O8: 66 | P8: =GETPIVOTDATA("Act Bund",$B$3,"Bundle Error",0)/GETPIVOTDATA("Act Bund",$B$3) -> 0.52380952 | R8: =P7+P8+P9+P6+P10 -> 0.98412698 | S8: =P7+P8+P9 -> 0.87301587 | T8: =P8 -> 0.52380952 | AL8: 1 | AM8: 30 | AN8: =ABS(AL8) -> 1 | AO8: =AL8^2 -> 1 | AQ8: % within ±2 | AR8: =IF(SUM(AM4:AM103)=0,NA(),SUMIFS(AM4:AM103,AL4:AL103,">=-2",AL4:AL103,"<=2")/SUM(AM4:AM103)) -> 0.98412698 | AS8: 0.98412698 | AT8: 0.98412698 | AU8: 0.97619048
B9: 1 | C9: 19 | D9: 6 | F9: 1 | G9: 1 | H9: 2 | I9: 1 | O9: 30 | P9: =GETPIVOTDATA("Act Bund",$B$3,"Bundle Error",1)/GETPIVOTDATA("Act Bund",$B$3) -> 0.23809524 | AL9: 2 | AM9: 10 | AN9: =ABS(AL9) -> 2 | AO9: =AL9^2 -> 4 | AQ9: % within ±5 | AR9: =IF(SUM(AM4:AM103)=0,NA(),SUMIFS(AM4:AM103,AL4:AL103,">=-5",AL4:AL103,"<=5")/SUM(AM4:AM103)) -> 0.99206349 | AS9: 0.99206349 | AT9: 0.99206349 | AU9: 0.99206349
B10: 2 | C10: 4 | D10: 3 | E10: 3 | O10: 10 | P10: =GETPIVOTDATA("Act Bund",$B$3,"Bundle Error",2)/GETPIVOTDATA("Act Bund",$B$3) -> 0.079365079 | AL10: 5 | AM10: 1 | AN10: =ABS(AL10) -> 5 | AO10: =AL10^2 -> 25 | AQ10: Mean Signed Deviation (MSD) | AR10: =IF(SUM(AM4:AM103)=0,NA(),SUMPRODUCT(AL4:AL103,AM4:AM103)/SUM(AM4:AM103)) -> 0.19047619 | AS10: 0.14285714 | AT10: 0.14285714 | AU10: 0.15873016
B11: 5 | K11: 1 | O11: 1 | P11: =GETPIVOTDATA("Act Bund",$B$3,"Bundle Error",5)/GETPIVOTDATA("Act Bund",$B$3) -> 0.0079365079 | AN11: =ABS(AL11) -> 0 | AO11: =AL11^2 -> 0 | AQ11: % Negative (OPT<ACTUAL) | AR11: =IF(SUM(AM4:AM103)=0,NA(),SUMIFS(AM4:AM103,AL4:AL103,"<0")/SUM(AM4:AM103)) -> 0.15079365 | AS11: 0.15873016 | AT11: 0.15873016 | AU11: 0.17460317
B12: Grand Total | C12: 72 | D12: 22 | E12: 9 | F12: 4 | G12: 5 | H12: 3 | I12: 4 | J12: 1 | K12: 3 | L12: 1 | M12: 1 | N12: 1 | O12: 126 | AN12: =ABS(AL12) -> 0 | AO12: =AL12^2 -> 0 | AQ12: % Positive (OPT>ACTUAL) | AR12: =IF(SUM(AM4:AM103)=0,NA(),SUMIFS(AM4:AM103,AL4:AL103,">0")/SUM(AM4:AM103)) -> 0.32539683 | AS12: 0.3015873 | AT12: 0.3015873 | AU12: 0.31746032
AN13: =ABS(AL13) -> 0 | AO13: =AL13^2 -> 0 | AQ13: Weighted MAD (2× neg penalty) | AR13: =IF(SUM(AM4:AM103)=0,NA(),(SUMPRODUCT((AL4:AL103<0)*2*ABS(AL4:AL103),AM4:AM103)+SUMPRODUCT((AL4:AL103>=0)*ABS(AL4:AL103),AM4:AM103))/SUM(AM4:AM103)) -> 0.92857143 | AS13: 0.92857143 | AT13: 0.92857143 | AU13: 0.96825397
C14: ~90% >0 | AN14: =ABS(AL14) -> 0 | AO14: =AL14^2 -> 0 | AQ14: Bias Reward (penalizes negative MSD) | AR14: =1 - MAX(0,-AR10)/(1+ABS(AR10)) -> 1 | AS14: 1 | AT14: 1 | AU14: 1
AN15: =ABS(AL15) -> 0 | AO15: =AL15^2 -> 0 | AQ15: Composite Optimization Score (0–1, higher=better) | AR15: =0.35*AR7 + 0.2*AR8 + 0.15*(1 - AR5/(1+AR5)) + 0.1*(1 - AR6/(1+AR6)) + 0.1*(1 - AR11) + 0.1*AR14 -> 0.82033835 | AS15: 0.82051392 | AT15: 0.82051392 | AU15: 0.81807804
AN16: =ABS(AL16) -> 0 | AO16: =AL16^2 -> 0
AN17: =ABS(AL17) -> 0 | AO17: =AL17^2 -> 0 | AQ17: Notes: Paste your Row Labels and Counts in columns A and B. All results update automatically.
AN18: =ABS(AL18) -> 0 | AO18: =AL18^2 -> 0
AN19: =ABS(AL19) -> 0 | AO19: =AL19^2 -> 0
AN20: =ABS(AL20) -> 0 | AO20: =AL20^2 -> 0
AN21: =ABS(AL21) -> 0 | AO21: =AL21^2 -> 0
AN22: =ABS(AL22) -> 0 | AO22: =AL22^2 -> 0
AN23: =ABS(AL23) -> 0 | AO23: =AL23^2 -> 0
AN24: =ABS(AL24) -> 0 | AO24: =AL24^2 -> 0
AN25: =ABS(AL25) -> 0 | AO25: =AL25^2 -> 0
AN26: =ABS(AL26) -> 0 | AO26: =AL26^2 -> 0
AN27: =ABS(AL27) -> 0 | AO27: =AL27^2 -> 0
AN28: =ABS(AL28) -> 0 | AO28: =AL28^2 -> 0
AN29: =ABS(AL29) -> 0 | AO29: =AL29^2 -> 0
... AN47: =ABS(AL47) -> 0 | AO47: =AL47^2 -> 0
B48: Count of Act Bund | C48: Column Labels | AN48: =ABS(AL48) -> 0 | AO48: =AL48^2 -> 0
B49: Row Labels | C49: 1 | D49: 2 | E49: 3 | F49: 4 | G49: 5 | H49: 6 | I49: 7 | J49: 8 | K49: 9 | L49: 11 | M49: 15 | N49: 33 | O49: Grand Total | AN49: =ABS(AL49) -> 0 | AO49: =AL49^2 -> 0
B50: -9 | O50: =SUM(C50:N50) -> 0 | P50: =O50/$O$57 -> 0 | Q50: =P52+P53+P54+P51+P55+P50+P56 -> 1 | AN50: =ABS(AL50) -> 0 | AO50: =AL50^2 -> 0
B51: -2 | O51: =SUM(C51:N51) -> 0 | P51: =O51/$O$57 -> 0 | AN51: =ABS(AL51) -> 0 | AO51: =AL51^2 -> 0
B52: -1 | D52: 7 | E52: 1 | G52: 2 | H52: 1 | O52: =SUM(C52:N52) -> 11 | P52: =O52/$O$57 -> 0.095652174 | AN52: =ABS(AL52) -> 0 | AO52: =AL52^2 -> 0
B53: 0 | C53: 49 | D53: 6 | E53: 5 | F53: 3 | G53: 2 | O53: =SUM(C53:N53) -> 65 | P53: =O53/$O$57 -> 0.56521739 | R53: =P52+P53+P54+P51+P55 -> 1 | S53: =P52+P53+P54 -> 0.91304348 | T53: =P53 -> 0.56521739 | AN53: =ABS(AL53) -> 0 | AO53: =AL53^2 -> 0
B54: 1 | C54: 19 | D54: 6 | F54: 1 | G54: 1 | H54: 2 | O54: =SUM(C54:N54) -> 29 | P54: =O54/$O$57 -> 0.25217391 | AN54: =ABS(AL54) -> 0 | AO54: =AL54^2 -> 0
B55: 2 | C55: 4 | D55: 3 | E55: 3 | O55: =SUM(C55:N55) -> 10 | P55: =O55/$O$57 -> 0.086956522 | AN55: =ABS(AL55) -> 0 | AO55: =AL55^2 -> 0
B56: 5 | O56: =SUM(C56:N56) -> 0 | P56: =O56/$O$57 -> 0 | AN56: =ABS(AL56) -> 0 | AO56: =AL56^2 -> 0
B57: Grand Total | C57: =SUM(C50:C56) -> 72 | D57: =SUM(D50:D56) -> 22 | E57: =SUM(E50:E56) -> 9 | F57: =SUM(F50:F56) -> 4 | G57: =SUM(G50:G56) -> 5 | H57: =SUM(H50:H56) -> 3 | I57: =SUM(I50:I56) -> 0 | J57: =SUM(J50:J56) -> 0 | ... O57: =SUM(O50:O56) -> 115 | AN57: =ABS(AL57) -> 0 | AO57: =AL57^2 -> 0
AN58: =ABS(AL58) -> 0 | AO58: =AL58^2 -> 0
...

Sheet PotvsActuals
A1: SOrderNbr | B1: Opt Bund | C1: Act Bund | D1: Bundle Error | E1: Opt_lbs | F1: Act_lbs | G1: lbs Error | H1: Review | I1: Image | J1: Comment
A2: 1011474 | B2: =IFERROR(_xlfn.MAXIFS(Optimized_Bundles!$C:$C, Optimized_Bundles!$B:$B, $A2), "") -> 1 | C2: 1 | D2: =B2-C2 -> 0 | E2: =IFERROR(_xlfn.MAXIFS(Optimized_Bundles!$O:$O, Optimized_Bundles!$B:$B, $A2), "") -> 1761 | F2: 1700 | G2: =E2-F2 -> 61 | H2: =G2/F2 -> 0.035882353
A3: 1013331 | B3: =IFERROR(_xlfn.MAXIFS(Optimized_Bundles!$C:$C, Optimized_Bundles!$B:$B, $A3), "") -> 5 | C3: 5 | D3: =B3-C3 -> 0 | E3: =IFERROR(_xlfn.MAXIFS(Optimized_Bundles!$O:$O, Optimized_Bundles!$B:$B, $A3), "") -> 4848 | F3: 4844 | G3: =E3-F3 -> 4 | H3: =G3/F3 -> 0.00082576383
A4: 1014092 | B4: =IFERROR(_xlfn.MAXIFS(Optimized_Bundles!$C:$C, Optimized_Bundles!$B:$B, $A4), "") -> 2 | C4: 2 | D4: =B4-C4 -> 0 | E4: =IFERROR(_xlfn.MAXIFS(Optimized_Bundles!$O:$O, Optimized_Bundles!$B:$B, $A4), "") -> 1535 | F4: 1444 | G4: =E4-F4 -> 91 | H4: =G4/F4 -> 0.063019391
A5: 1014159 | B5: =IFERROR(_xlfn.MAXIFS(Optimized_Bundles!$C:$C, Optimized_Bundles!$B:$B, $A5), "") -> 1 | C5: 1 | D5: =B5-C5 -> 0 | E5: =IFERROR(_xlfn.MAXIFS(Optimized_Bundles!$O:$O, Optimized_Bundles!$B:$B, $A5), "") -> 143 | F5: 134 | G5: =E5-F5 -> 9 | H5: =G5/F5 -> 0.067164179
A6: 1014176 | B6: =IFERROR(_xlfn.MAXIFS(Optimized_Bundles!$C:$C, Optimized_Bundles!$B:$B, $A6), "") -> 3 | C6: 3 | D6: =B6-C6 -> 0 | E6: =IFERROR(_xlfn.MAXIFS(Optimized_Bundles!$O:$O, Optimized_Bundles!$B:$B, $A6), "") -> 3922 | F6: 3377 | G6: =E6-F6 -> 545 | H6: =G6/F6 -> 0.16138585
A7: 1014183 | B7: =IFERROR(_xlfn.MAXIFS(Optimized_Bundles!$C:$C, Optimized_Bundles!$B:$B, $A7), "") -> 1 | C7: 1 | D7: =B7-C7 -> 0 | E7: =IFERROR(_xlfn.MAXIFS(Optimized_Bundles!$O:$O, Optimized_Bundles!$B:$B, $A7), "") -> 325 | F7: 304 | G7: =E7-F7 -> 21 | H7: =G7/F7 -> 0.069078947
A8: 1013749 | B8: =IFERROR(_xlfn.MAXIFS(Optimized_Bundles!$C:$C, Optimized_Bundles!$B:$B, $A8), "") -> 3 | C8: 2 | D8: =B8-C8 -> 1 | E8: =IFERROR(_xlfn.MAXIFS(Optimized_Bundles!$O:$O, Optimized_Bundles!$B:$B, $A8), "") -> 3201 | F8: 2983 | G8: =E8-F8 -> 218 | H8: =G8/F8 -> 0.073080791 | I8: ?
A9: 1014039 | B9: =IFERROR(_xlfn.MAXIFS(Optimized_Bundles!$C:$C, Optimized_Bundles!$B:$B, $A9), "") -> 6 | C9: 7 | D9: =B9-C9 -> -1 | E9: =IFERROR(_xlfn.MAXIFS(Optimized_Bundles!$O:$O, Optimized_Bundles!$B:$B, $A9), "") -> 11412 | F9: 11616 | G9: =E9-F9 -> -204 | H9: =G9/F9 -> -0.017561983
A10: 1014218 | B10: =IFERROR(_xlfn.MAXIFS(Optimized_Bundles!$C:$C, Optimized_Bundles!$B:$B, $A10), "") -> 1 | C10: 1 | D10: =B10-C10 -> 0 | E10: =IFERROR(_xlfn.MAXIFS(Optimized_Bundles!$O:$O, Optimized_Bundles!$B:$B, $A10), "") -> 136 | F10: 130 | G10: =E10-F10 -> 6 | H10: =G10/F10 -> 0.046153846
A11: 1013449 | B11: =IFERROR(_xlfn.MAXIFS(Optimized_Bundles!$C:$C, Optimized_Bundles!$B:$B, $A11), "") -> 3 | C11: 2 | D11: =B11-C11 -> 1 | E11: =IFERROR(_xlfn.MAXIFS(Optimized_Bundles!$O:$O, Optimized_Bundles!$B:$B, $A11), "") -> 1072 | F11: 1016 | G11: =E11-F11 -> 56 | H11: =G11/F11 -> 0.05511811
A12: 1013904 | B12: =IFERROR(_xlfn.MAXIFS(Optimized_Bundles!$C:$C, Optimized_Bundles!$B:$B, $A12), "") -> 5 | C12: 4 | D12: =B12-C12 -> 1 | E12: =IFERROR(_xlfn.MAXIFS(Optimized_Bundles!$O:$O, Optimized_Bundles!$B:$B, $A12), "") -> 3575 | F12: 3583 | G12: =E12-F12 -> -8 | H12: =G12/F12 -> -0.0022327658
A13: 1014240 | B13: =IFERROR(_xlfn.MAXIFS(Optimized_Bundles!$C:$C, Optimized_Bundles!$B:$B, $A13), "") -> 1 | C13: 2 | D13: =B13-C13 -> -1 | E13: =IFERROR(_xlfn.MAXIFS(Optimized_Bundles!$O:$O, Optimized_Bundles!$B:$B, $A13), "") -> 1134 | F13: 528 | G13: =E13-F13 -> 606 | H13: =G13/F13 -> 1.1477273
A14: 1014054 | B14: =IFERROR(_xlfn.MAXIFS(Optimized_Bundles!$C:$C, Optimized_Bundles!$B:$B, $A14), "") -> 1 | C14: 1 | D14: =B14-C14 -> 0 | E14: =IFERROR(_xlfn.MAXIFS(Optimized_Bundles!$O:$O, Optimized_Bundles!$B:$B, $A14), "") -> 834 | F14: 860 | G14: =E14-F14 -> -26 | H14: =G14/F14 -> -0.030232558
A15: 1014121 | B15: =IFERROR(_xlfn.MAXIFS(Optimized_Bundles!$C:$C, Optimized_Bundles!$B:$B, $A15), "") -> 2 | C15: 1 | D15: =B15-C15 -> 1 | E15: =IFERROR(_xlfn.MAXIFS(Optimized_Bundles!$O:$O, Optimized_Bundles!$B:$B, $A15), "") -> 683 | F15: 602 | G15: =E15-F15 -> 81 | H15: =G15/F15 -> 0.1345515
A16: 1013988 | B16: =IFERROR(_xlfn.MAXIFS(Optimized_Bundles!$C:$C, Optimized_Bundles!$B:$B, $A16), "") -> 4 | C16: 2 | D16: =B16-C16 -> 2 | E16: =IFERROR(_xlfn.MAXIFS(Optimized_Bundles!$O:$O, Optimized_Bundles!$B:$B, $A16), "") -> 3172 | F16: 3036 | G16: =E16-F16 -> 136 | H16: =G16/F16 -> 0.044795784
A17: 1014332 | B17: =IFERROR(_xlfn.MAXIFS(Optimized_Bundles!$C:$C, Optimized_Bundles!$B:$B, $A17), "") -> 2 | C17: 1 | D17: =B17-C17 -> 1 | E17: =IFERROR(_xlfn.MAXIFS(Optimized_Bundles!$O:$O, Optimized_Bundles!$B:$B, $A17), "") -> 640 | F17: 608 | G17: =E17-F17 -> 32 | H17: =G17/F17 -> 0.052631579
A18: 1014242 | B18: =IFERROR(_xlfn.MAXIFS(Optimized_Bundles!$C:$C, Optimized_Bundles!$B:$B, $A18), "") -> 1 | C18: 1 | D18: =B18-C18 -> 0 | E18: =IFERROR(_xlfn.MAXIFS(Optimized_Bundles!$O:$O, Optimized_Bundles!$B:$B, $A18), "") -> 183 | F18: 170 | G18: =E18-F18 -> 13 | H18: =G18/F18 -> 0.076470588
A19: 1014293 | B19: =IFERROR(_xlfn.MAXIFS(Optimized_Bundles!$C:$C, Optimized_Bundles!$B:$B, $A19), "") -> 3 | C19: 3 | D19: =B19-C19 -> 0 | E19: =IFERROR(_xlfn.MAXIFS(Optimized_Bundles!$O:$O, Optimized_Bundles!$B:$B, $A19), "") -> 3857 | F19: 3439 | G19: =E19-F19 -> 418 | H19: =G19/F19 -> 0.12154696
A20: 1014344 | B20: =IFERROR(_xlfn.MAXIFS(Optimized_Bundles!$C:$C, Optimized_Bundles!$B:$B, $A20), "") -> 3 | C20: 2 | D20: =B20-C20 -> 1 | E20: =IFERROR(_xlfn.MAXIFS(Optimized_Bundles!$O:$O, Optimized_Bundles!$B:$B, $A20), "") -> 4068 | F20: 3882 | G20: =E20-F20 -> 186 | H20: =G20/F20 -> 0.047913447
... A124: 1014550 | B124: =IFERROR(_xlfn.MAXIFS(Optimized_Bundles!$C:$C, Optimized_Bundles!$B:$B, $A124), "") -> 1 | C124: 2 | D124: =B124-C124 -> -1 | E124: =IFERROR(_xlfn.MAXIFS(Optimized_Bundles!$O:$O, Optimized_Bundles!$B:$B, $A124), "") -> 72 | F124: 82 | G124: =E124-F124 -> -10 | H124: =G124/F124 -> -0.12195122
A125: 1014532 | B125: =IFERROR(_xlfn.MAXIFS(Optimized_Bundles!$C:$C, Optimized_Bundles!$B:$B, $A125), "") -> 1 | C125: 1 | D125: =B125-C125 -> 0 | E125: =IFERROR(_xlfn.MAXIFS(Optimized_Bundles!$O:$O, Optimized_Bundles!$B:$B, $A125), "") -> 170 | G125: =E125-F125 -> 170 | H125: =G125/F125 -> #DIV/0!
A126: 1014554 | B126: =IFERROR(_xlfn.MAXIFS(Optimized_Bundles!$C:$C, Optimized_Bundles!$B:$B, $A126), "") -> 1 | C126: 1 | D126: =B126-C126 -> 0 | E126: =IFERROR(_xlfn.MAXIFS(Optimized_Bundles!$O:$O, Optimized_Bundles!$B:$B, $A126), "") -> 35 | F126: 123 | G126: =E126-F126 -> -88 | H126: =G126/F126 -> -0.71544715
A127: 1014567 | B127: =IFERROR(_xlfn.MAXIFS(Optimized_Bundles!$C:$C, Optimized_Bundles!$B:$B, $A127), "") -> 1 | C127: 1 | D127: =B127-C127 -> 0 | E127: =IFERROR(_xlfn.MAXIFS(Optimized_Bundles!$O:$O, Optimized_Bundles!$B:$B, $A127), "") -> 790 | F127: 811 | G127: =E127-F127 -> -21 | H127: =G127/F127 -> -0.025893958
F128: =SUM(F17:F127) -> 294505 | G128: =SUM(G17:G127) -> 181 | H128: =G128/F128 -> 0.00061459058

Sheet Optimized_Bundles
A1: OrderType | B1: OrderNbr | C1: BundleNbr | D1: Bdl_Override | E1: Machine | F1: ReviewedBy | G1: ApprovedBy | H1: InventoryID | I1: Quantity | J1: Pcs/Bundle | K1: TotalPcs | L1: Width_in | M1: Height_in | N1: Length_in | O1: Weight_lbs | P1: UOM | Q1: Description | R1: ShipTo | S1: AddressLine1 | T1: AddressLine2 | U1: City | V1: State | W1: Country | X1: Status | Y1: OrderDate | Z1: ProdReleaseDate | AA1: SchedShipDate | AB1: TargetArrival | AC1: NotBefore | AD1: ShipVia | AE1: LastModifiedOn | AF1: OptimizedOn
A2: SO | B2: 1014393 | C2: ALL | H2: Total_Order | I2: 29 | J2: N/A | K2: 74 | L2: N/A | M2: N/A | N2: N/A | O2: 178 | Q2: Total Order Summary | R2: MacArthur Co. (Belgrade, MT) | S2: 111 Andrea Drive | U2: Belgrade | V2: MT | W2: US | X2: Shipping | Y2: 2025-09-04 | Z2: 2025-09-05 | AA2: 2025-09-05 | AD2: COMMONCARRIER | AE2: 2025-09-12 | AF2: 2025-11-20
A3: SO | B3: 1014393 | C3: 0_ALL | H3: Missing_SKUs | I3: 2 | J3: N/A | K3: N/A | L3: N/A | M3: N/A | N3: N/A | O3: N/A | Q3: Missing SKUs Summary | R3: MacArthur Co. (Belgrade, MT) | S3: 111 Andrea Drive | U3: Belgrade | V3: MT | W3: US | X3: Shipping | Y3: 2025-09-04 | Z3: 2025-09-05 | AA3: 2025-09-05 | AD3: COMMONCARRIER | AE3: 2025-09-12 | AF3: 2025-11-20
A4: SO | B4: 1014393 | C4: 0 | H4: TUP.90200 | I4: 8 | J4: N/A | K4: N/A | L4: N/A | M4: N/A | N4: N/A | O4: N/A | P4: EA | Q4: Touch Up Pen for Onyx Black Finish | R4: MacArthur Co. (Belgrade, MT) | S4: 111 Andrea Drive | U4: Belgrade | V4: MT | W4: US | X4: Shipping | Y4: 2025-09-04 | Z4: 2025-09-05 | AA4: 2025-09-05 | AD4: COMMONCARRIER | AE4: 2025-09-12 | AF4: 2025-11-20
A5: SO | B5: 1014393 | C5: 0 | H5: TUP.80450 | I5: 1 | J5: N/A | K5: N/A | L5: N/A | M5: N/A | N5: N/A | O5: N/A | P5: EA | Q5: Touch Up Pen for Bedrock & Pebble Finishes | R5: MacArthur Co. (Belgrade, MT) | S5: 111 Andrea Drive | U5: Belgrade | V5: MT | W5: US | X5: Shipping | Y5: 2025-09-04 | Z5: 2025-09-05 | AA5: 2025-09-05 | AD5: COMMONCARRIER | AE5: 2025-09-12 | AF5: 2025-11-20
A6: SO | B6: 1014393 | C6: 1_ALL | E6: MIXED | H6: Total_Bundle_1 | I6: 29 | J6: N/A | K6: 74 | L6: 9 | M6: 10 | N6: 145 | O6: 178 | Q6: Bundle 1 Summary | R6: MacArthur Co. (Belgrade, MT) | S6: 111 Andrea Drive | U6: Belgrade | V6: MT | W6: US | X6: Shipping | Y6: 2025-09-04 | Z6: 2025-09-05 | AA6: 2025-09-05 | AD6: COMMONCARRIER | AE6: 2025-09-12 | AF6: 2025-11-20
A7: SO | B7: 1014393 | C7: 1 | E7: MIXED | H7: 6V.72.15BRK | I7: 1 | J7: 8 | K7: 8 | L7: 2 | M7: 7 | N7: 72 | O7: 26 | P7: EA | Q7: 6" V-Groove 6 Feet (Premium Bedrock) | R7: MacArthur Co. (Belgrade, MT) | S7: 111 Andrea Drive | U7: Belgrade | V7: MT | W7: US | X7: Shipping | Y7: 2025-09-04 | Z7: 2025-09-05 | AA7: 2025-09-05 | AD7: COMMONCARRIER | AE7: 2025-09-12 | AF7: 2025-11-20
A8: SO | B8: 1014393 | C8: 1 | E8: MIXED | H8: 6VR.72.15BCY | I8: 1 | J8: 8 | K8: 8 | L8: 2 | M8: 7 | N8: 72 | O8: 28 | P8: EA | Q8: 6" V-Groove - Rib 6 Feet (Premium Burnt Cherry) | R8: MacArthur Co. (Belgrade, MT) | S8: 111 Andrea Drive | U8: Belgrade | V8: MT | W8: US | X8: Shipping | Y8: 2025-09-04 | Z8: 2025-09-05 | AA8: 2025-09-05 | AD8: COMMONCARRIER | AE8: 2025-09-12 | AF8: 2025-11-20
A9: SO | B9: 1014393 | C9: 1 | E9: MIXED | H9: 6VR.72.15WOK | I9: 1 | J9: 8 | K9: 8 | L9: 2 | M9: 7 | N9: 72 | O9: 28 | P9: EA | Q9: 6" V-Groove - Rib 6 Feet (Premium White Oak) | R9: MacArthur Co. (Belgrade, MT) | S9: 111 Andrea Drive | U9: Belgrade | V9: MT | W9: US | X9: Shipping | Y9: 2025-09-04 | Z9: 2025-09-05 | AA9: 2025-09-05 | AD9: COMMONCARRIER | AE9: 2025-09-12 | AF9: 2025-11-20
A10: SO | B10: 1014393 | C10: 1 | E10: MIXED | H10: 6VR.72.15GHL | I10: 1 | J10: 8 | K10: 8 | L10: 2 | M10: 7 | N10: 72 | O10: 28 | P10: EA | Q10: 6" V-Groove - Rib 6 Feet (Premium Grey Hemlock) | R10: MacArthur Co. (Belgrade, MT) | S10: 111 Andrea Drive | U10: Belgrade | V10: MT | W10: US | X10: Shipping | Y10: 2025-09-04 | Z10: 2025-09-05 | AA10: 2025-09-05 | AD10: COMMONCARRIER | AE10: 2025-09-12 | AF10: 2025-11-20
A11: SO | B11: 1014393 | C11: 1 | E11: MIXED | H11: JT23.72.15BRK_Partial | I11: 1 | J11: 3 | K11: 3 | L11: 0 | M11: 3 | N11: 72 | O11: 4 | P11: EA | Q11: 7/8" J-Track 6 Feet (Premium Bedrock) | R11: MacArthur Co. (Belgrade, MT) | S11: 111 Andrea Drive | U11: Belgrade | V11: MT | W11: US | X11: Shipping | Y11: 2025-09-04 | Z11: 2025-09-05 | AA11: 2025-09-05 | AD11: COMMONCARRIER | AE11: 2025-09-12 | AF11: 2025-11-20
A12: SO | B12: 1014393 | C12: 1 | E12: MIXED | H12: JT23.72.15BCY_Partial | I12: 1 | J12: 2 | K12: 2 | L12: 0 | M12: 3 | N12: 72 | O12: 2 | P12: EA | Q12: 7/8" J-Track 6 Feet (Premium Burnt Cherry) | R12: MacArthur Co. (Belgrade, MT) | S12: 111 Andrea Drive | U12: Belgrade | V12: MT | W12: US | X12: Shipping | Y12: 2025-09-04 | Z12: 2025-09-05 | AA12: 2025-09-05 | AD12: COMMONCARRIER | AE12: 2025-09-12 | AF12: 2025-11-20
A13: SO | B13: 1014393 | C13: 1 | E13: MIXED | H13: 2SS.72.15OBL_Partial | I13: 1 | J13: 4 | K13: 4 | L13: 0 | M13: 4 | N13: 72 | O13: 4 | P13: EA | Q13: 1-7/8" Starter Strip (Slotted) 6 Feet (Premium Onyx Black) | R13: MacArthur Co. (Belgrade, MT) | S13: 111 Andrea Drive | U13: Belgrade | V13: MT | W13: US | X13: Shipping | Y13: 2025-09-04 | Z13: 2025-09-05 | AA13: 2025-09-05 | AD13: COMMONCARRIER | AE13: 2025-09-12 | AF13: 2025-11-20
A14: SO | B14: 1014393 | C14: 1 | E14: MIXED | H14: JT23.72.15WOK_Partial | I14: 1 | J14: 2 | K14: 2 | L14: 0 | M14: 3 | N14: 72 | O14: 2 | P14: EA | Q14: 7/8" J-Track 6 Feet (Premium White Oak) | R14: MacArthur Co. (Belgrade, MT) | S14: 111 Andrea Drive | U14: Belgrade | V14: MT | W14: US | X14: Shipping | Y14: 2025-09-04 | Z14: 2025-09-05 | AA14: 2025-09-05 | AD14: COMMONCARRIER | AE14: 2025-09-12 | AF14: 2025-11-20
A15: SO | B15: 1014393 | C15: 1 | E15: MIXED | H15: JT23.72.15GHL_Partial | I15: 1 | J15: 2 | K15: 2 | L15: 0 | M15: 3 | N15: 72 | O15: 2 | P15: EA | Q15: 7/8" J-Track 6 Feet (Premium Grey Hemlock) | R15: MacArthur Co. (Belgrade, MT) | S15: 111 Andrea Drive | U15: Belgrade | V15: MT | W15: US | X15: Shipping | Y15: 2025-09-04 | Z15: 2025-09-05 | AA15: 2025-09-05 | AD15: COMMONCARRIER | AE15: 2025-09-12 | AF15: 2025-11-20
A16: SO | B16: 1014393 | C16: 1 | E16: MIXED | H16: 6V.72.15BRK_Partial | I16: 1 | J16: 1 | K16: 1 | L16: 0 | M16: 7 | N16: 72 | O16: 3 | P16: EA | Q16: 6" V-Groove 6 Feet (Premium Bedrock) | R16: MacArthur Co. (Belgrade, MT) | S16: 111 Andrea Drive | U16: Belgrade | V16: MT | W16: US | X16: Shipping | Y16: 2025-09-04 | Z16: 2025-09-05 | AA16: 2025-09-05 | AD16: COMMONCARRIER | AE16: 2025-09-12 | AF16: 2025-11-20
A17: SO | B17: 1014393 | C17: 1 | E17: MIXED | H17: 6VR.72.15BCY_Partial | I17: 1 | J17: 1 | K17: 1 | L17: 0 | M17: 7 | N17: 72 | O17: 3 | P17: EA | Q17: 6" V-Groove - Rib 6 Feet (Premium Burnt Cherry) | R17: MacArthur Co. (Belgrade, MT) | S17: 111 Andrea Drive | U17: Belgrade | V17: MT | W17: US | X17: Shipping | Y17: 2025-09-04 | Z17: 2025-09-05 | AA17: 2025-09-05 | AD17: COMMONCARRIER | AE17: 2025-09-12 | AF17: 2025-11-20
A18: SO | B18: 1014393 | C18: 1 | E18: MIXED | H18: 6VR.72.15WOK_Partial | I18: 1 | J18: 1 | K18: 1 | L18: 0 | M18: 7 | N18: 72 | O18: 3 | P18: EA | Q18: 6" V-Groove - Rib 6 Feet (Premium White Oak) | R18: MacArthur Co. (Belgrade, MT) | S18: 111 Andrea Drive | U18: Belgrade | V18: MT | W18: US | X18: Shipping | Y18: 2025-09-04 | Z18: 2025-09-05 | AA18: 2025-09-05 | AD18: COMMONCARRIER | AE18: 2025-09-12 | AF18: 2025-11-20
... A27: SO | B27: 1014393 | C27: 1 | E27: MIXED | H27: JT23C.72.15GHL_Partial | I27: 1 | J27: 1 | K27: 1 | L27: 0 | M27: 2 | N27: 72 | O27: 1 | P27: EA | Q27: 7/8" Two Piece J-Track Cap 6 Feet (Premium Grey Hemlock) | R27: MacArthur Co. (Belgrade, MT) | S27: 111 Andrea Drive | U27: Belgrade | V27: MT | W27: US | X27: Shipping | Y27: 2025-09-04 | Z27: 2025-09-05 | AA27: 2025-09-05 | AD27: COMMONCARRIER | AE27: 2025-09-12 | AF27: 2025-11-20
A28: SO | B28: 1014393 | C28: 1 | E28: MIXED | H28: Pack_62Filler | I28: 1 | J28: 1 | K28: 1 | L28: 2 | M28: 6 | N28: 144 | O28: 5 | Q28: 6"x2" FILLER BOX | R28: MacArthur Co. (Belgrade, MT) | S28: 111 Andrea Drive | U28: Belgrade | V28: MT | W28: US | X28: Shipping | Y28: 2025-09-04 | Z28: 2025-09-05 | AA28: 2025-09-05 | AD28: COMMONCARRIER | AE28: 2025-09-12 | AF28: 2025-11-20
A29: SO | B29: 1014393 | C29: 1 | E29: MIXED | H29: Pack_Angle_3680 | I29: 1 | J29: 4 | K29: 4 | L29: 3 | M29: 0 | N29: 144 | O29: 12 | Q29: PRINTED ANGLEBOARD | R29: MacArthur Co. (Belgrade, MT) | S29: 111 Andrea Drive | U29: Belgrade | V29: MT | W29: US | X29: Shipping | Y29: 2025-09-04 | Z29: 2025-09-05 | AA29: 2025-09-05 | AD29: COMMONCARRIER | AE29: 2025-09-12 | AF29: 2025-11-20
A30: SO | B30: 1014393 | C30: 1 | E30: MIXED | H30: Pack_1x4x19_Dun_3680 | I30: 1 | J30: 2 | K30: 2 | L30: 4 | M30: 1 | N30: 19 | O30: 2 | Q30: 1" X 4" X 19" DUNNAGE | R30: MacArthur Co. (Belgrade, MT) | S30: 111 Andrea Drive | U30: Belgrade | V30: MT | W30: US | X30: Shipping | Y30: 2025-09-04 | Z30: 2025-09-05 | AA30: 2025-09-05 | AD30: COMMONCARRIER | AE30: 2025-09-12 | AF30: 2025-11-20
A31: SO | B31: 1014393 | C31: 1 | E31: MIXED | H31: Pack_2x3x19_Dun_3680 | I31: 1 | J31: 2 | K31: 2 | L31: 3 | M31: 1 | N31: 19 | O31: 4 | Q31: 2" X 3" X 19" DUNNAGE | R31: MacArthur Co. (Belgrade, MT) | S31: 111 Andrea Drive | U31: Belgrade | V31: MT | W31: US | X31: Shipping | Y31: 2025-09-04 | Z31: 2025-09-05 | AA31: 2025-09-05 | AD31: COMMONCARRIER | AE31: 2025-09-12 | AF31: 2025-11-20
A32: SO | B32: 1014393 | C32: 1 | E32: MIXED | H32: Pack_Sub_Bndl_Wrp_3680 | I32: 1 | J32: 2 | K32: 2 | L32: 19 | M32: 0 | N32: 144 | O32: 5 | Q32: Sub-Bundle Wrap - Crepe Paper/Stretch Film | R32: MacArthur Co. (Belgrade, MT) | S32: 111 Andrea Drive | U32: Belgrade | V32: MT | W32: US | X32: Shipping | Y32: 2025-09-04 | Z32: 2025-09-05 | AA32: 2025-09-05 | AD32: COMMONCARRIER | AE32: 2025-09-12 | AF32: 2025-11-20
A33: SO | B33: 1014393 | C33: 1 | E33: MIXED | H33: Pack_Mst_Bndl_Wrp_3680 | I33: 1 | J33: 2 | K33: 2 | L33: 19 | M33: 0 | N33: 144 | O33: 1 | Q33: Master Bundle - Stretch Wrap | R33: MacArthur Co. (Belgrade, MT) | S33: 111 Andrea Drive | U33: Belgrade | V33: MT | W33: US | X33: Shipping | Y33: 2025-09-04 | Z33: 2025-09-05 | AA33: 2025-09-05 | AD33: COMMONCARRIER | AE33: 2025-09-12 | AF33: 2025-11-20
A34: SO | B34: 1014393 | C34: 1 | E34: MIXED | H34: Pack_Pad_8_3680 | I34: 2 | J34: 2 | K34: 4 | L34: 8 | M34: 0 | N34: 144 | O34: 2 | Q34: PAD - 8-1/2" X 144" DW ECT #3 WHITE | R34: MacArthur Co. (Belgrade, MT) | S34: 111 Andrea Drive | U34: Belgrade | V34: MT | W34: US | X34: Shipping | Y34: 2025-09-04 | Z34: 2025-09-05 | AA34: 2025-09-05 | AD34: COMMONCARRIER | AE34: 2025-09-12 | AF34: 2025-11-20
A36: RM | B36: 1000070 | C36: 0_ALL | H36: Missing_SKUs | I36: 10 | J36: N/A | K36: N/A | L36: N/A | M36: N/A | N36: N/A | O36: N/A | Q36: Missing SKUs Summary | R36: Cortland Improvements LLC | S36: 2901 NE 1st Avenue | U36: Miami | V36: FL | W36: US | X36: Open | Y36: 2025-06-19 | Z36: 2025-06-19 | AA36: 2025-06-19 | AD36: COMMONCARRIER | AE36: 2025-06-19 | AF36: 2025-11-20
A37: RM | B37: 1000070 | C37: 0 | H37: TUP.71200 | I37: 27 | J37: N/A | K37: N/A | L37: N/A | M37: N/A | N37: N/A | O37: N/A | P37: EA | Q37: Touch Up Pen for Light National Walnut Finish | R37: Cortland Improvements LLC | S37: 2901 NE 1st Avenue | U37: Miami | V37: FL | W37: US | X37: Open | Y37: 2025-06-19 | Z37: 2025-06-19 | AA37: 2025-06-19 | AD37: COMMONCARRIER | AE37: 2025-06-19 | AF37: 2025-11-20
A39: SO | B39: 1012965 | C39: ALL | H39: Total_Order | I39: 1204 | J39: N/A | K39: 5235 | L39: N/A | M39: N/A | N39: N/A | O39: 25675 | Q39: Total Order Summary | R39: Ecole Maquatua School | S39: 7 Maquatua Wemindji | U39: Wemindji | V39: QC | W39: CA | X39: Shipping | Y39: 2025-05-20 | Z39: 2025-07-16 | AA39: 2025-07-16 | AD39: COMMONCARRIER | AE39: 2025-07-31 | AF39: 2025-11-20
A40: SO | B40: 1012965 | C40: 0_ALL | H40: Missing_SKUs | I40: 169 | J40: N/A | K40: N/A | L40: N/A | M40: N/A | N40: N/A | O40: N/A | Q40: Missing SKUs Summary | R40: Ecole Maquatua School | S40: 7 Maquatua Wemindji | U40: Wemindji | V40: QC | W40: CA | X40: Shipping | Y40: 2025-05-20 | Z40: 2025-07-16 | AA40: 2025-07-16 | AD40: COMMONCARRIER | AE40: 2025-07-31 | AF40: 2025-11-20
A41: SO | B41: 1012965 | C41: 0 | H41: 2ESLV.2.15BRD | I41: 54 | J41: N/A | K41: N/A | L41: N/A | M41: N/A | N41: N/A | O41: N/A | P41: EA | Q41: 1-1/2" T&G End Sleeve - 2TGURK - Component 2 2 inches (Premium Brick Red) | R41: Ecole Maquatua School | S41: 7 Maquatua Wemindji | U41: Wemindji | V41: QC | W41: CA | X41: Shipping | Y41: 2025-05-20 | Z41: 2025-07-16 | AA41: 2025-07-16 | AD41: COMMONCARRIER | AE41: 2025-07-31 | AF41: 2025-11-20
A42: SO | B42: 1012965 | C42: 0 | H42: HITCH.HD.87 | I42: 115 | J42: N/A | K42: N/A | L42: N/A | M42: N/A | N42: N/A | O42: N/A | P42: BOX12 | Q42: HITCH HD Clip - 8.75" Tube - Box of 12 | R42: Ecole Maquatua School | S42: 7 Maquatua Wemindji | U42: Wemindji | V42: QC | W42: CA | X42: Shipping | Y42: 2025-05-20 | Z42: 2025-07-16 | AA42: 2025-07-16 | AD42: COMMONCARRIER | AE42: 2025-07-31 | AF42: 2025-11-20
A43: SO | B43: 1012965 | C43: 1_ALL | E43: MACH1 | H43: Total_Bundle_1 | I43: 23 | J43: N/A | K43: 160 | L43: 22 | M43: 14 | N43: 289 | O43: 1963 | Q43: Bundle 1 Summary | R43: Ecole Maquatua School | S43: 7 Maquatua Wemindji | U43: Wemindji | V43: QC | W43: CA | X43: Shipping | Y43: 2025-05-20 | Z43: 2025-07-16 | AA43: 2025-07-16 | AD43: COMMONCARRIER | AE43: 2025-07-31 | AF43: 2025-11-20
A44: SO | B44: 1012965 | C44: 1 | E44: MACH1 | H44: 6PSP.289.15BRD | I44: 16 | J44: 8 | K44: 128 | L44: 2 | M44: 7 | N44: 289 | O44: 118 | P44: BOX8 | Q44: 6" Smooth Plank 24 feet (Premium Brick Red) Box of 8 | R44: Ecole Maquatua School | S44: 7 Maquatua Wemindji | U44: Wemindji | V44: QC | W44: CA | X44: Shipping | Y44: 2025-05-20 | Z44: 2025-07-16 | AA44: 2025-07-16 | AD44: COMMONCARRIER | AE44: 2025-07-31 | AF44: 2025-11-20
A45: SO | B45: 1012965 | C45: 1 | E45: MACH1 | H45: Pack_Angle_7340 | I45: 1 | J45: 8 | K45: 8 | L45: 3 | M45: 0 | N45: 288 | O45: 24 | Q45: PRINTED ANGLEBOARD | R45: Ecole Maquatua School | S45: 7 Maquatua Wemindji | U45: Wemindji | V45: QC | W45: CA | X45: Shipping | Y45: 2025-05-20 | Z45: 2025-07-16 | AA45: 2025-07-16 | AD45: COMMONCARRIER | AE45: 2025-07-31 | AF45: 2025-11-20
A46: SO | B46: 1012965 | C46: 1 | E46: MACH1 | H46: Pack_1x4x19_Dun_7340 | I46: 1 | J46: 4 | K46: 4 | L46: 4 | M46: 1 | N46: 38 | O46: 4 | Q46: 1" X 4" X 19" DUNNAGE | R46: Ecole Maquatua School | S46: 7 Maquatua Wemindji | U46: Wemindji | V46: QC | W46: CA | X46: Shipping | Y46: 2025-05-20 | Z46: 2025-07-16 | AA46: 2025-07-16 | AD46: COMMONCARRIER | AE46: 2025-07-31 | AF46: 2025-11-20
A47: SO | B47: 1012965 | C47: 1 | E47: MACH1 | H47: Pack_2x3x19_Dun_7340 | I47: 1 | J47: 4 | K47: 4 | L47: 3 | M47: 1 | N47: 38 | O47: 8 | Q47: 2" X 3" X 19" DUNNAGE | R47: Ecole Maquatua School | S47: 7 Maquatua Wemindji | U47: Wemindji | V47: QC | W47: CA | X47: Shipping | Y47: 2025-05-20 | Z47: 2025-07-16 | AA47: 2025-07-16 | AD47: COMMONCARRIER | AE47: 2025-07-31 | AF47: 2025-11-20
A48: SO | B48: 1012965 | C48: 1 | E48: MACH1 | H48: Pack_Sub_Bndl_Wrp_7340 | I48: 1 | J48: 4 | K48: 4 | L48: 19 | M48: 0 | N48: 288 | O48: 10 | Q48: Sub-Bundle Wrap - Crepe Paper/Stretch Film | R48: Ecole Maquatua School | S48: 7 Maquatua Wemindji | U48: Wemindji | V48: QC | W48: CA | X48: Shipping | Y48: 2025-05-20 | Z48: 2025-07-16 | AA48: 2025-07-16 | AD48: COMMONCARRIER | AE48: 2025-07-31 | AF48: 2025-11-20
A49: SO | B49: 1012965 | C49: 1 | E49: MACH1 | H49: Pack_Mst_Bndl_Wrp_7340 | I49: 1 | J49: 4 | K49: 4 | L49: 19 | M49: 0 | N49: 288 | O49: 2 | Q49: Master Bundle - Stretch Wrap | R49: Ecole Maquatua School | S49: 7 Maquatua Wemindji | U49: Wemindji | V49: QC | W49: CA | X49: Shipping | Y49: 2025-05-20 | Z49: 2025-07-16 | AA49: 2025-07-16 | AD49: COMMONCARRIER | AE49: 2025-07-31 | AF49: 2025-11-20
A50: SO | B50: 1012965 | C50: 1 | E50: MACH1 | H50: Pack_Pad_19_7340 | I50: 1 | J50: 4 | K50: 4 | L50: 19 | M50: 0 | N50: 288 | O50: 12 | Q50: PAD - 19" X 144" DW ECT #3 WHITE | R50: Ecole Maquatua School | S50: 7 Maquatua Wemindji | U50: Wemindji | V50: QC | W50: CA | X50: Shipping | Y50: 2025-05-20 | Z50: 2025-07-16 | AA50: 2025-07-16 | AD50: COMMONCARRIER | AE50: 2025-07-31 | AF50: 2025-11-20
...
